[2024-05-28T18:53:56.774+0000] {taskinstance.py:1165} INFO - Dependencies all met for <TaskInstance: dag_extract.transform_sales_orders_task manual__2024-05-28T18:53:54.587734+00:00 [queued]>
[2024-05-28T18:53:56.785+0000] {taskinstance.py:1165} INFO - Dependencies all met for <TaskInstance: dag_extract.transform_sales_orders_task manual__2024-05-28T18:53:54.587734+00:00 [queued]>
[2024-05-28T18:53:56.786+0000] {taskinstance.py:1362} INFO - 
--------------------------------------------------------------------------------
[2024-05-28T18:53:56.786+0000] {taskinstance.py:1363} INFO - Starting attempt 1 of 1
[2024-05-28T18:53:56.787+0000] {taskinstance.py:1364} INFO - 
--------------------------------------------------------------------------------
[2024-05-28T18:53:56.801+0000] {taskinstance.py:1383} INFO - Executing <Task(PythonOperator): transform_sales_orders_task> on 2024-05-28 18:53:54.587734+00:00
[2024-05-28T18:53:56.804+0000] {standard_task_runner.py:55} INFO - Started process 731 to run task
[2024-05-28T18:53:56.807+0000] {standard_task_runner.py:82} INFO - Running: ['***', 'tasks', 'run', 'dag_extract', 'transform_sales_orders_task', 'manual__2024-05-28T18:53:54.587734+00:00', '--job-id', '51', '--raw', '--subdir', 'DAGS_FOLDER/dag_extract.py', '--cfg-path', '/tmp/tmppfqdvelj']
[2024-05-28T18:53:56.808+0000] {standard_task_runner.py:83} INFO - Job 51: Subtask transform_sales_orders_task
[2024-05-28T18:53:56.865+0000] {task_command.py:376} INFO - Running <TaskInstance: dag_extract.transform_sales_orders_task manual__2024-05-28T18:53:54.587734+00:00 [running]> on host 9a04f700e4be
[2024-05-28T18:53:56.938+0000] {taskinstance.py:1592} INFO - Exporting the following env vars:
AIRFLOW_CTX_DAG_OWNER=***
AIRFLOW_CTX_DAG_ID=dag_extract
AIRFLOW_CTX_TASK_ID=transform_sales_orders_task
AIRFLOW_CTX_EXECUTION_DATE=2024-05-28T18:53:54.587734+00:00
AIRFLOW_CTX_TRY_NUMBER=1
AIRFLOW_CTX_DAG_RUN_ID=manual__2024-05-28T18:53:54.587734+00:00
[2024-05-28T18:53:56.943+0000] {taskinstance.py:1851} ERROR - Task failed with exception
Traceback (most recent call last):
  File "/home/airflow/.local/lib/python3.7/site-packages/airflow/operators/python.py", line 175, in execute
    return_value = self.execute_callable()
  File "/home/airflow/.local/lib/python3.7/site-packages/airflow/operators/python.py", line 193, in execute_callable
    return self.python_callable(*self.op_args, **self.op_kwargs)
  File "/opt/airflow/dags/transform_sales_orders.py", line 46, in main
    order by date(date_order)"""
psycopg2.errors.DatatypeMismatch: column "ctl_datetime" is of type timestamp with time zone but expression is of type bigint
LINE 7:                 sum(case when type='sales' then 1 else 0 end...
                        ^
HINT:  You will need to rewrite or cast the expression.

[2024-05-28T18:53:56.957+0000] {taskinstance.py:1406} INFO - Marking task as FAILED. dag_id=dag_extract, task_id=transform_sales_orders_task, execution_date=20240528T185354, start_date=20240528T185356, end_date=20240528T185356
[2024-05-28T18:53:56.969+0000] {standard_task_runner.py:105} ERROR - Failed to execute job 51 for task transform_sales_orders_task (column "ctl_datetime" is of type timestamp with time zone but expression is of type bigint
LINE 7:                 sum(case when type='sales' then 1 else 0 end...
                        ^
HINT:  You will need to rewrite or cast the expression.
; 731)
[2024-05-28T18:53:57.059+0000] {local_task_job.py:164} INFO - Task exited with return code 1
[2024-05-28T18:53:57.080+0000] {local_task_job.py:273} INFO - 0 downstream tasks scheduled from follow-on schedule check
