[2024-05-28T19:12:32.266+0000] {taskinstance.py:1165} INFO - Dependencies all met for <TaskInstance: dag_extract.extract_orders_task manual__2024-05-28T19:12:31.660706+00:00 [queued]>
[2024-05-28T19:12:32.278+0000] {taskinstance.py:1165} INFO - Dependencies all met for <TaskInstance: dag_extract.extract_orders_task manual__2024-05-28T19:12:31.660706+00:00 [queued]>
[2024-05-28T19:12:32.279+0000] {taskinstance.py:1362} INFO - 
--------------------------------------------------------------------------------
[2024-05-28T19:12:32.279+0000] {taskinstance.py:1363} INFO - Starting attempt 1 of 1
[2024-05-28T19:12:32.280+0000] {taskinstance.py:1364} INFO - 
--------------------------------------------------------------------------------
[2024-05-28T19:12:32.295+0000] {taskinstance.py:1383} INFO - Executing <Task(PythonOperator): extract_orders_task> on 2024-05-28 19:12:31.660706+00:00
[2024-05-28T19:12:32.379+0000] {standard_task_runner.py:55} INFO - Started process 1646 to run task
[2024-05-28T19:12:32.384+0000] {standard_task_runner.py:82} INFO - Running: ['***', 'tasks', 'run', 'dag_extract', 'extract_orders_task', 'manual__2024-05-28T19:12:31.660706+00:00', '--job-id', '71', '--raw', '--subdir', 'DAGS_FOLDER/dag_extract.py', '--cfg-path', '/tmp/tmp747yjzdo']
[2024-05-28T19:12:32.385+0000] {standard_task_runner.py:83} INFO - Job 71: Subtask extract_orders_task
[2024-05-28T19:12:32.442+0000] {task_command.py:376} INFO - Running <TaskInstance: dag_extract.extract_orders_task manual__2024-05-28T19:12:31.660706+00:00 [running]> on host 9a04f700e4be
[2024-05-28T19:12:32.509+0000] {taskinstance.py:1592} INFO - Exporting the following env vars:
AIRFLOW_CTX_DAG_OWNER=***
AIRFLOW_CTX_DAG_ID=dag_extract
AIRFLOW_CTX_TASK_ID=extract_orders_task
AIRFLOW_CTX_EXECUTION_DATE=2024-05-28T19:12:31.660706+00:00
AIRFLOW_CTX_TRY_NUMBER=1
AIRFLOW_CTX_DAG_RUN_ID=manual__2024-05-28T19:12:31.660706+00:00
[2024-05-28T19:12:32.624+0000] {taskinstance.py:1851} ERROR - Task failed with exception
Traceback (most recent call last):
  File "/home/airflow/.local/lib/python3.7/site-packages/airflow/operators/python.py", line 175, in execute
    return_value = self.execute_callable()
  File "/home/airflow/.local/lib/python3.7/site-packages/airflow/operators/python.py", line 193, in execute_callable
    return self.python_callable(*self.op_args, **self.op_kwargs)
  File "/opt/airflow/dags/extract_orders.py", line 82, in main
    ctl_datetime,
psycopg2.errors.UndefinedColumn: column "ctl_datetime" of relation "orders" does not exist
LINE 1: ...            cancelDate, subject, category, brand, ctl_dateti...
                                                             ^

[2024-05-28T19:12:32.636+0000] {taskinstance.py:1406} INFO - Marking task as FAILED. dag_id=dag_extract, task_id=extract_orders_task, execution_date=20240528T191231, start_date=20240528T191232, end_date=20240528T191232
[2024-05-28T19:12:32.648+0000] {standard_task_runner.py:105} ERROR - Failed to execute job 71 for task extract_orders_task (column "ctl_datetime" of relation "orders" does not exist
LINE 1: ...            cancelDate, subject, category, brand, ctl_dateti...
                                                             ^
; 1646)
[2024-05-28T19:12:32.675+0000] {local_task_job.py:164} INFO - Task exited with return code 1
[2024-05-28T19:12:32.705+0000] {local_task_job.py:273} INFO - 0 downstream tasks scheduled from follow-on schedule check
