[2024-05-26T17:39:29.020+0000] {taskinstance.py:1165} INFO - Dependencies all met for <TaskInstance: dag_extract.extract_orders manual__2024-05-26T17:39:28.445277+00:00 [queued]>
[2024-05-26T17:39:29.033+0000] {taskinstance.py:1165} INFO - Dependencies all met for <TaskInstance: dag_extract.extract_orders manual__2024-05-26T17:39:28.445277+00:00 [queued]>
[2024-05-26T17:39:29.034+0000] {taskinstance.py:1362} INFO - 
--------------------------------------------------------------------------------
[2024-05-26T17:39:29.035+0000] {taskinstance.py:1363} INFO - Starting attempt 1 of 1
[2024-05-26T17:39:29.035+0000] {taskinstance.py:1364} INFO - 
--------------------------------------------------------------------------------
[2024-05-26T17:39:29.052+0000] {taskinstance.py:1383} INFO - Executing <Task(PythonOperator): extract_orders> on 2024-05-26 17:39:28.445277+00:00
[2024-05-26T17:39:29.056+0000] {standard_task_runner.py:55} INFO - Started process 12922 to run task
[2024-05-26T17:39:29.059+0000] {standard_task_runner.py:82} INFO - Running: ['***', 'tasks', 'run', 'dag_extract', 'extract_orders', 'manual__2024-05-26T17:39:28.445277+00:00', '--job-id', '5', '--raw', '--subdir', 'DAGS_FOLDER/dag_extract.py', '--cfg-path', '/tmp/tmp6qr4k93x']
[2024-05-26T17:39:29.060+0000] {standard_task_runner.py:83} INFO - Job 5: Subtask extract_orders
[2024-05-26T17:39:29.123+0000] {task_command.py:376} INFO - Running <TaskInstance: dag_extract.extract_orders manual__2024-05-26T17:39:28.445277+00:00 [running]> on host 9a04f700e4be
[2024-05-26T17:39:29.278+0000] {taskinstance.py:1592} INFO - Exporting the following env vars:
AIRFLOW_CTX_DAG_OWNER=***
AIRFLOW_CTX_DAG_ID=dag_extract
AIRFLOW_CTX_TASK_ID=extract_orders
AIRFLOW_CTX_EXECUTION_DATE=2024-05-26T17:39:28.445277+00:00
AIRFLOW_CTX_TRY_NUMBER=1
AIRFLOW_CTX_DAG_RUN_ID=manual__2024-05-26T17:39:28.445277+00:00
[2024-05-26T17:39:29.401+0000] {taskinstance.py:1851} ERROR - Task failed with exception
Traceback (most recent call last):
  File "/home/airflow/.local/lib/python3.7/site-packages/airflow/operators/python.py", line 175, in execute
    return_value = self.execute_callable()
  File "/home/airflow/.local/lib/python3.7/site-packages/airflow/operators/python.py", line 193, in execute_callable
    return self.python_callable(*self.op_args, **self.op_kwargs)
  File "/opt/airflow/dags/extract_orders.py", line 25, in main
    cursor.execute("truncate table orders")
psycopg2.errors.UndefinedTable: relation "orders" does not exist

[2024-05-26T17:39:29.415+0000] {taskinstance.py:1406} INFO - Marking task as FAILED. dag_id=dag_extract, task_id=extract_orders, execution_date=20240526T173928, start_date=20240526T173929, end_date=20240526T173929
[2024-05-26T17:39:29.430+0000] {standard_task_runner.py:105} ERROR - Failed to execute job 5 for task extract_orders (relation "orders" does not exist
; 12922)
[2024-05-26T17:39:29.472+0000] {local_task_job.py:164} INFO - Task exited with return code 1
[2024-05-26T17:39:29.495+0000] {local_task_job.py:273} INFO - 0 downstream tasks scheduled from follow-on schedule check
